[2023-05-13T19:02:54.462+0000] {taskinstance.py:1125} INFO - Dependencies all met for dep_context=non-requeueable deps ti=<TaskInstance: hypothesis1.insert_data manual__2023-05-13T19:02:49.723843+00:00 [queued]>
[2023-05-13T19:02:54.491+0000] {taskinstance.py:1125} INFO - Dependencies all met for dep_context=requeueable deps ti=<TaskInstance: hypothesis1.insert_data manual__2023-05-13T19:02:49.723843+00:00 [queued]>
[2023-05-13T19:02:54.494+0000] {taskinstance.py:1331} INFO - Starting attempt 1 of 1
[2023-05-13T19:02:54.545+0000] {taskinstance.py:1350} INFO - Executing <Task(PythonOperator): insert_data> on 2023-05-13 19:02:49.723843+00:00
[2023-05-13T19:02:54.560+0000] {standard_task_runner.py:57} INFO - Started process 432 to run task
[2023-05-13T19:02:54.570+0000] {standard_task_runner.py:84} INFO - Running: ['***', 'tasks', 'run', 'hypothesis1', 'insert_data', 'manual__2023-05-13T19:02:49.723843+00:00', '--job-id', '11', '--raw', '--subdir', 'DAGS_FOLDER/dag_hypothesis1.py', '--cfg-path', '/tmp/tmpsc4ckzfp']
[2023-05-13T19:02:54.578+0000] {standard_task_runner.py:85} INFO - Job 11: Subtask insert_data
[2023-05-13T19:02:54.715+0000] {task_command.py:410} INFO - Running <TaskInstance: hypothesis1.insert_data manual__2023-05-13T19:02:49.723843+00:00 [running]> on host 9a745d3878c0
[2023-05-13T19:02:54.942+0000] {taskinstance.py:1570} INFO - Exporting env vars: AIRFLOW_CTX_DAG_OWNER='***' AIRFLOW_CTX_DAG_ID='hypothesis1' AIRFLOW_CTX_TASK_ID='insert_data' AIRFLOW_CTX_EXECUTION_DATE='2023-05-13T19:02:49.723843+00:00' AIRFLOW_CTX_TRY_NUMBER='1' AIRFLOW_CTX_DAG_RUN_ID='manual__2023-05-13T19:02:49.723843+00:00'
[2023-05-13T19:02:54.949+0000] {logging_mixin.py:149} INFO - Postgres connect success
[2023-05-13T19:02:54.974+0000] {base.py:73} INFO - Using connection ID 'qiberry' for task execution.
[2023-05-13T19:02:54.996+0000] {taskinstance.py:1847} ERROR - Task failed with exception
Traceback (most recent call last):
  File "/home/airflow/.local/lib/python3.7/site-packages/airflow/operators/python.py", line 181, in execute
    return_value = self.execute_callable()
  File "/home/airflow/.local/lib/python3.7/site-packages/airflow/operators/python.py", line 198, in execute_callable
    return self.python_callable(*self.op_args, **self.op_kwargs)
  File "/opt/airflow/dags/dag_hypothesis1.py", line 28, in insert_data_py
    src.insert_rows(table=table_name, rows=[row])
  File "/home/airflow/.local/lib/python3.7/site-packages/airflow/providers/common/sql/hooks/sql.py", line 467, in insert_rows
    cur.execute(sql, values)
psycopg2.errors.UndefinedTable: relation "public.cars" does not exist
LINE 1: INSERT INTO public.cars  VALUES ('vin','back_legroom','bed',...
                    ^

[2023-05-13T19:02:55.024+0000] {taskinstance.py:1373} INFO - Marking task as FAILED. dag_id=hypothesis1, task_id=insert_data, execution_date=20230513T190249, start_date=20230513T190254, end_date=20230513T190255
[2023-05-13T19:02:55.058+0000] {standard_task_runner.py:109} ERROR - Failed to execute job 11 for task insert_data (relation "public.cars" does not exist
LINE 1: INSERT INTO public.cars  VALUES ('vin','back_legroom','bed',...
                    ^
; 432)
[2023-05-13T19:02:55.107+0000] {local_task_job_runner.py:232} INFO - Task exited with return code 1
[2023-05-13T19:02:55.150+0000] {taskinstance.py:2674} INFO - 0 downstream tasks scheduled from follow-on schedule check
