[2023-05-13T19:28:39.010+0000] {taskinstance.py:1125} INFO - Dependencies all met for dep_context=non-requeueable deps ti=<TaskInstance: hypothesis1_2.insert_data manual__2023-05-13T19:28:21.468032+00:00 [queued]>
[2023-05-13T19:28:39.031+0000] {taskinstance.py:1125} INFO - Dependencies all met for dep_context=requeueable deps ti=<TaskInstance: hypothesis1_2.insert_data manual__2023-05-13T19:28:21.468032+00:00 [queued]>
[2023-05-13T19:28:39.033+0000] {taskinstance.py:1331} INFO - Starting attempt 1 of 1
[2023-05-13T19:28:39.058+0000] {taskinstance.py:1350} INFO - Executing <Task(PythonOperator): insert_data> on 2023-05-13 19:28:21.468032+00:00
[2023-05-13T19:28:39.068+0000] {standard_task_runner.py:57} INFO - Started process 853 to run task
[2023-05-13T19:28:39.076+0000] {standard_task_runner.py:84} INFO - Running: ['***', 'tasks', 'run', 'hypothesis1_2', 'insert_data', 'manual__2023-05-13T19:28:21.468032+00:00', '--job-id', '29', '--raw', '--subdir', 'DAGS_FOLDER/dag_hypothesis1_2.py', '--cfg-path', '/tmp/tmpkr24h7tg']
[2023-05-13T19:28:39.093+0000] {standard_task_runner.py:85} INFO - Job 29: Subtask insert_data
[2023-05-13T19:28:39.285+0000] {task_command.py:410} INFO - Running <TaskInstance: hypothesis1_2.insert_data manual__2023-05-13T19:28:21.468032+00:00 [running]> on host 9a745d3878c0
[2023-05-13T19:28:39.505+0000] {taskinstance.py:1570} INFO - Exporting env vars: AIRFLOW_CTX_DAG_OWNER='***' AIRFLOW_CTX_DAG_ID='hypothesis1_2' AIRFLOW_CTX_TASK_ID='insert_data' AIRFLOW_CTX_EXECUTION_DATE='2023-05-13T19:28:21.468032+00:00' AIRFLOW_CTX_TRY_NUMBER='1' AIRFLOW_CTX_DAG_RUN_ID='manual__2023-05-13T19:28:21.468032+00:00'
[2023-05-13T19:28:39.509+0000] {logging_mixin.py:149} INFO - Postgres connect success
[2023-05-13T19:28:39.533+0000] {base.py:73} INFO - Using connection ID 'qiberry' for task execution.
[2023-05-13T19:28:39.552+0000] {taskinstance.py:1847} ERROR - Task failed with exception
Traceback (most recent call last):
  File "/home/airflow/.local/lib/python3.7/site-packages/airflow/operators/python.py", line 181, in execute
    return_value = self.execute_callable()
  File "/home/airflow/.local/lib/python3.7/site-packages/airflow/operators/python.py", line 198, in execute_callable
    return self.python_callable(*self.op_args, **self.op_kwargs)
  File "/opt/airflow/dags/dag_hypothesis1_2.py", line 27, in insert_data_py
    src.insert_rows(table=table_name, rows=[row])
  File "/home/airflow/.local/lib/python3.7/site-packages/airflow/providers/common/sql/hooks/sql.py", line 467, in insert_rows
    cur.execute(sql, values)
psycopg2.errors.InvalidTextRepresentation: invalid input syntax for type integer: ""
LINE 1: INSERT INTO public.cars  VALUES ('','make_name','power','pri...
                                         ^

[2023-05-13T19:28:39.589+0000] {taskinstance.py:1373} INFO - Marking task as FAILED. dag_id=hypothesis1_2, task_id=insert_data, execution_date=20230513T192821, start_date=20230513T192839, end_date=20230513T192839
[2023-05-13T19:28:39.613+0000] {standard_task_runner.py:109} ERROR - Failed to execute job 29 for task insert_data (invalid input syntax for type integer: ""
LINE 1: INSERT INTO public.cars  VALUES ('','make_name','power','pri...
                                         ^
; 853)
[2023-05-13T19:28:39.661+0000] {local_task_job_runner.py:232} INFO - Task exited with return code 1
[2023-05-13T19:28:39.695+0000] {taskinstance.py:2674} INFO - 0 downstream tasks scheduled from follow-on schedule check
