[2023-05-13T22:17:31.937+0000] {taskinstance.py:1125} INFO - Dependencies all met for dep_context=non-requeueable deps ti=<TaskInstance: hypothesis2.insert_data manual__2023-05-13T22:17:17.147738+00:00 [queued]>
[2023-05-13T22:17:32.008+0000] {taskinstance.py:1125} INFO - Dependencies all met for dep_context=requeueable deps ti=<TaskInstance: hypothesis2.insert_data manual__2023-05-13T22:17:17.147738+00:00 [queued]>
[2023-05-13T22:17:32.013+0000] {taskinstance.py:1331} INFO - Starting attempt 1 of 1
[2023-05-13T22:17:32.067+0000] {taskinstance.py:1350} INFO - Executing <Task(PythonOperator): insert_data> on 2023-05-13 22:17:17.147738+00:00
[2023-05-13T22:17:32.085+0000] {standard_task_runner.py:57} INFO - Started process 2373 to run task
[2023-05-13T22:17:32.104+0000] {standard_task_runner.py:84} INFO - Running: ['***', 'tasks', 'run', 'hypothesis2', 'insert_data', 'manual__2023-05-13T22:17:17.147738+00:00', '--job-id', '99', '--raw', '--subdir', 'DAGS_FOLDER/dag_hypothesis2.py', '--cfg-path', '/tmp/tmpf_mt0ehw']
[2023-05-13T22:17:32.118+0000] {standard_task_runner.py:85} INFO - Job 99: Subtask insert_data
[2023-05-13T22:17:32.269+0000] {task_command.py:410} INFO - Running <TaskInstance: hypothesis2.insert_data manual__2023-05-13T22:17:17.147738+00:00 [running]> on host 9a745d3878c0
[2023-05-13T22:17:32.482+0000] {taskinstance.py:1570} INFO - Exporting env vars: AIRFLOW_CTX_DAG_OWNER='***' AIRFLOW_CTX_DAG_ID='hypothesis2' AIRFLOW_CTX_TASK_ID='insert_data' AIRFLOW_CTX_EXECUTION_DATE='2023-05-13T22:17:17.147738+00:00' AIRFLOW_CTX_TRY_NUMBER='1' AIRFLOW_CTX_DAG_RUN_ID='manual__2023-05-13T22:17:17.147738+00:00'
[2023-05-13T22:17:32.486+0000] {logging_mixin.py:149} INFO - Postgres connect success
[2023-05-13T22:17:32.492+0000] {taskinstance.py:1847} ERROR - Task failed with exception
Traceback (most recent call last):
  File "/home/airflow/.local/lib/python3.7/site-packages/airflow/operators/python.py", line 181, in execute
    return_value = self.execute_callable()
  File "/home/airflow/.local/lib/python3.7/site-packages/airflow/operators/python.py", line 198, in execute_callable
    return self.python_callable(*self.op_args, **self.op_kwargs)
  File "/opt/airflow/dags/dag_hypothesis2.py", line 27, in insert_data_py
    if (row['horsepower'] != ''):
TypeError: list indices must be integers or slices, not str
[2023-05-13T22:17:32.515+0000] {taskinstance.py:1373} INFO - Marking task as FAILED. dag_id=hypothesis2, task_id=insert_data, execution_date=20230513T221717, start_date=20230513T221731, end_date=20230513T221732
[2023-05-13T22:17:32.541+0000] {standard_task_runner.py:109} ERROR - Failed to execute job 99 for task insert_data (list indices must be integers or slices, not str; 2373)
[2023-05-13T22:17:32.604+0000] {local_task_job_runner.py:232} INFO - Task exited with return code 1
[2023-05-13T22:17:32.661+0000] {taskinstance.py:2674} INFO - 0 downstream tasks scheduled from follow-on schedule check
