[2023-05-13T21:41:09.435+0000] {taskinstance.py:1125} INFO - Dependencies all met for dep_context=non-requeueable deps ti=<TaskInstance: hypothesis2.select_data manual__2023-05-13T21:40:12.166408+00:00 [queued]>
[2023-05-13T21:41:09.450+0000] {taskinstance.py:1125} INFO - Dependencies all met for dep_context=requeueable deps ti=<TaskInstance: hypothesis2.select_data manual__2023-05-13T21:40:12.166408+00:00 [queued]>
[2023-05-13T21:41:09.452+0000] {taskinstance.py:1331} INFO - Starting attempt 1 of 1
[2023-05-13T21:41:09.473+0000] {taskinstance.py:1350} INFO - Executing <Task(PythonOperator): select_data> on 2023-05-13 21:40:12.166408+00:00
[2023-05-13T21:41:09.481+0000] {standard_task_runner.py:57} INFO - Started process 1945 to run task
[2023-05-13T21:41:09.488+0000] {standard_task_runner.py:84} INFO - Running: ['***', 'tasks', 'run', 'hypothesis2', 'select_data', 'manual__2023-05-13T21:40:12.166408+00:00', '--job-id', '68', '--raw', '--subdir', 'DAGS_FOLDER/dag_hypothesis2.py', '--cfg-path', '/tmp/tmp1sqs73s7']
[2023-05-13T21:41:09.492+0000] {standard_task_runner.py:85} INFO - Job 68: Subtask select_data
[2023-05-13T21:41:09.570+0000] {task_command.py:410} INFO - Running <TaskInstance: hypothesis2.select_data manual__2023-05-13T21:40:12.166408+00:00 [running]> on host 9a745d3878c0
[2023-05-13T21:41:09.691+0000] {taskinstance.py:1570} INFO - Exporting env vars: AIRFLOW_CTX_DAG_OWNER='***' AIRFLOW_CTX_DAG_ID='hypothesis2' AIRFLOW_CTX_TASK_ID='select_data' AIRFLOW_CTX_EXECUTION_DATE='2023-05-13T21:40:12.166408+00:00' AIRFLOW_CTX_TRY_NUMBER='1' AIRFLOW_CTX_DAG_RUN_ID='manual__2023-05-13T21:40:12.166408+00:00'
[2023-05-13T21:41:09.707+0000] {base.py:73} INFO - Using connection ID 'qiberry' for task execution.
[2023-05-13T21:41:09.714+0000] {logging_mixin.py:149} INFO - Postgres connect success
[2023-05-13T21:41:09.717+0000] {taskinstance.py:1847} ERROR - Task failed with exception
Traceback (most recent call last):
  File "/home/airflow/.local/lib/python3.7/site-packages/airflow/operators/python.py", line 181, in execute
    return_value = self.execute_callable()
  File "/home/airflow/.local/lib/python3.7/site-packages/airflow/operators/python.py", line 198, in execute_callable
    return self.python_callable(*self.op_args, **self.op_kwargs)
  File "/opt/airflow/dags/dag_hypothesis2.py", line 78, in select_data_py
    if str(horsepowers) != 'None':
UnboundLocalError: local variable 'horsepowers' referenced before assignment
[2023-05-13T21:41:09.733+0000] {taskinstance.py:1373} INFO - Marking task as FAILED. dag_id=hypothesis2, task_id=select_data, execution_date=20230513T214012, start_date=20230513T214109, end_date=20230513T214109
[2023-05-13T21:41:09.750+0000] {standard_task_runner.py:109} ERROR - Failed to execute job 68 for task select_data (local variable 'horsepowers' referenced before assignment; 1945)
[2023-05-13T21:41:09.780+0000] {local_task_job_runner.py:232} INFO - Task exited with return code 1
[2023-05-13T21:41:09.806+0000] {taskinstance.py:2674} INFO - 0 downstream tasks scheduled from follow-on schedule check
