[2023-05-13T10:15:09.305+0000] {taskinstance.py:1125} INFO - Dependencies all met for dep_context=non-requeueable deps ti=<TaskInstance: qiberry.insert_data manual__2023-05-13T10:15:00.778829+00:00 [queued]>
[2023-05-13T10:15:09.322+0000] {taskinstance.py:1125} INFO - Dependencies all met for dep_context=requeueable deps ti=<TaskInstance: qiberry.insert_data manual__2023-05-13T10:15:00.778829+00:00 [queued]>
[2023-05-13T10:15:09.324+0000] {taskinstance.py:1331} INFO - Starting attempt 1 of 1
[2023-05-13T10:15:09.345+0000] {taskinstance.py:1350} INFO - Executing <Task(PythonOperator): insert_data> on 2023-05-13 10:15:00.778829+00:00
[2023-05-13T10:15:09.354+0000] {standard_task_runner.py:57} INFO - Started process 395 to run task
[2023-05-13T10:15:09.362+0000] {standard_task_runner.py:84} INFO - Running: ['***', 'tasks', 'run', 'qiberry', 'insert_data', 'manual__2023-05-13T10:15:00.778829+00:00', '--job-id', '10', '--raw', '--subdir', 'DAGS_FOLDER/dag_laba3.py', '--cfg-path', '/tmp/tmpjb_0yf7g']
[2023-05-13T10:15:09.374+0000] {standard_task_runner.py:85} INFO - Job 10: Subtask insert_data
[2023-05-13T10:15:09.557+0000] {task_command.py:410} INFO - Running <TaskInstance: qiberry.insert_data manual__2023-05-13T10:15:00.778829+00:00 [running]> on host bfb86d9b8782
[2023-05-13T10:15:09.710+0000] {taskinstance.py:1570} INFO - Exporting env vars: AIRFLOW_CTX_DAG_OWNER='***' AIRFLOW_CTX_DAG_ID='qiberry' AIRFLOW_CTX_TASK_ID='insert_data' AIRFLOW_CTX_EXECUTION_DATE='2023-05-13T10:15:00.778829+00:00' AIRFLOW_CTX_TRY_NUMBER='1' AIRFLOW_CTX_DAG_RUN_ID='manual__2023-05-13T10:15:00.778829+00:00'
[2023-05-13T10:15:09.718+0000] {logging_mixin.py:149} INFO - Postgres connect success
[2023-05-13T10:15:09.736+0000] {base.py:73} INFO - Using connection ID 'qiberry' for task execution.
[2023-05-13T10:15:09.747+0000] {taskinstance.py:1847} ERROR - Task failed with exception
Traceback (most recent call last):
  File "/home/airflow/.local/lib/python3.7/site-packages/airflow/operators/python.py", line 181, in execute
    return_value = self.execute_callable()
  File "/home/airflow/.local/lib/python3.7/site-packages/airflow/operators/python.py", line 198, in execute_callable
    return self.python_callable(*self.op_args, **self.op_kwargs)
  File "/opt/airflow/dags/dag_laba3.py", line 18, in insert_data_py
    src.insert_rows(table='public.planes', rows=[row])
  File "/home/airflow/.local/lib/python3.7/site-packages/airflow/providers/common/sql/hooks/sql.py", line 467, in insert_rows
    cur.execute(sql, values)
psycopg2.errors.UndefinedTable: relation "public.planes" does not exist
LINE 1: INSERT INTO public.planes  VALUES ('Firstname','Lastname','A...
                    ^

[2023-05-13T10:15:09.768+0000] {taskinstance.py:1373} INFO - Marking task as FAILED. dag_id=qiberry, task_id=insert_data, execution_date=20230513T101500, start_date=20230513T101509, end_date=20230513T101509
[2023-05-13T10:15:09.787+0000] {standard_task_runner.py:109} ERROR - Failed to execute job 10 for task insert_data (relation "public.planes" does not exist
LINE 1: INSERT INTO public.planes  VALUES ('Firstname','Lastname','A...
                    ^
; 395)
[2023-05-13T10:15:09.823+0000] {local_task_job_runner.py:232} INFO - Task exited with return code 1
[2023-05-13T10:15:09.875+0000] {taskinstance.py:2674} INFO - 0 downstream tasks scheduled from follow-on schedule check
